multiprocessing.pool.RemoteTraceback: 
"""
Traceback (most recent call last):
  File "/home/jhyang/anaconda3/envs/isyn2/lib/python3.9/multiprocessing/pool.py", line 125, in worker
    result = (True, func(*args, **kwds))
  File "/home/jhyang/anaconda3/envs/isyn2/lib/python3.9/multiprocessing/pool.py", line 48, in mapstar
    return list(map(*args))
  File "/mnt/CODES/inorganic_synthesis/execute.py", line 32, in exc
    R.main(R.args)
  File "/mnt/CODES/inorganic_synthesis/run_gcvae.py", line 111, in main
    writer.add_histogram(f'Z/{sfx}', output['z'], epoch)
  File "/home/jhyang/anaconda3/envs/isyn2/lib/python3.9/site-packages/torch/utils/tensorboard/writer.py", line 526, in add_histogram
    histogram(tag, values, bins, max_bins=max_bins), global_step, walltime
  File "/home/jhyang/anaconda3/envs/isyn2/lib/python3.9/site-packages/torch/utils/tensorboard/summary.py", line 483, in histogram
    hist = make_histogram(values.astype(float), bins, max_bins)
  File "/home/jhyang/anaconda3/envs/isyn2/lib/python3.9/site-packages/torch/utils/tensorboard/summary.py", line 528, in make_histogram
    raise ValueError("The histogram is empty, please file a bug report.")
ValueError: The histogram is empty, please file a bug report.
"""

The above exception was the direct cause of the following exception:

Traceback (most recent call last):
  File "/mnt/CODES/inorganic_synthesis/execute.py", line 35, in <module>
    pool.map(exc, [i for i in range(600)])
  File "/home/jhyang/anaconda3/envs/isyn2/lib/python3.9/multiprocessing/pool.py", line 364, in map
    return self._map_async(func, iterable, mapstar, chunksize).get()
  File "/home/jhyang/anaconda3/envs/isyn2/lib/python3.9/multiprocessing/pool.py", line 771, in get
    raise self._value
ValueError: The histogram is empty, please file a bug report.
multiprocessing.pool.RemoteTraceback: 
"""
Traceback (most recent call last):
  File "/home/jhyang/anaconda3/envs/isyn2/lib/python3.9/multiprocessing/pool.py", line 125, in worker
    result = (True, func(*args, **kwds))
  File "/home/jhyang/anaconda3/envs/isyn2/lib/python3.9/multiprocessing/pool.py", line 48, in mapstar
    return list(map(*args))
  File "/home/jhyang/WORKSPACES/CODES/inorganic_synthesis/execute.py", line 32, in exc
    R.main(R.args)
  File "/home/jhyang/WORKSPACES/CODES/inorganic_synthesis/run_gcvae_class.py", line 112, in main
    writer.add_histogram(f'Z/{sfx}', output['z'], epoch)
  File "/home/jhyang/anaconda3/envs/isyn2/lib/python3.9/site-packages/torch/utils/tensorboard/writer.py", line 526, in add_histogram
    histogram(tag, values, bins, max_bins=max_bins), global_step, walltime
  File "/home/jhyang/anaconda3/envs/isyn2/lib/python3.9/site-packages/torch/utils/tensorboard/summary.py", line 483, in histogram
    hist = make_histogram(values.astype(float), bins, max_bins)
  File "/home/jhyang/anaconda3/envs/isyn2/lib/python3.9/site-packages/torch/utils/tensorboard/summary.py", line 528, in make_histogram
    raise ValueError("The histogram is empty, please file a bug report.")
ValueError: The histogram is empty, please file a bug report.
"""

The above exception was the direct cause of the following exception:

Traceback (most recent call last):
  File "/home/jhyang/WORKSPACES/CODES/inorganic_synthesis/execute.py", line 35, in <module>
    pool.map(exc, [i for i in range(600)])
  File "/home/jhyang/anaconda3/envs/isyn2/lib/python3.9/multiprocessing/pool.py", line 364, in map
    return self._map_async(func, iterable, mapstar, chunksize).get()
  File "/home/jhyang/anaconda3/envs/isyn2/lib/python3.9/multiprocessing/pool.py", line 771, in get
    raise self._value
ValueError: The histogram is empty, please file a bug report.
